Workbook

Sheet Cronograma
A1: Nome da Tarefa | B1: Duração | C1: Início | D1: Término | E1: Predecessoras
A2: HOOK UP FABRICAÇÃO | B2: 43 dias | C2: 46227.375 | D2: 46287.75
A3: Assinatura do Contrato / Kick Ok | B3: 0 dias | C3: 46227.375 | D3: 46227.375
A4: Mobilização | B4: 15 dias | C4: 46227.375 | D4: 46247.75 | E4: 2
A5: Retirada do Material e Deslocamento ate o local de fabricação | B5: 3 dias | C5: 46230.375 | D5: 46232.75 | E5: 3II+1 dia
A6: 1º Lote | B6: 12 dias | C6: 46234.375 | D6: 46251.75
A7: Spoletamento 1ºLote | B7: 5 dias | C7: 46234.375 | D7: 46240.75 | E7: 3II+5 dias
A8: Fabricação 1º Lote | B8: 8 dias | C8: 46239.375 | D8: 46248.75 | E8: 6II+3 dias
A9: Entrega no SITE 1º Lote | B9: 1 dia | C9: 46251.375 | D9: 46251.75 | E9: 7
A10: 2º Lote | B10: 17 dias | C10: 46241.375 | D10: 46265.75
A11: Spoletamento 2º Lote | B11: 5 dias | C11: 46241.375 | D11: 46247.75 | E11: 6
A12: Fabricação 2º Lote | B12: 13 dias | C12: 46246.375 | D12: 46262.75 | E12: 10II+3 dias
A13: Entrega no SITE 2º Lote | B13: 1 dia | C13: 46265.375 | D13: 46265.75 | E13: 11
A14: 3º Lote | B14: 23 dias | C14: 46248.375 | D14: 46280.75
A15: Spoletamento 3º Lote | B15: 5 dias | C15: 46248.375 | D15: 46254.75 | E15: 10
A16: Fabricação 3º Lote | B16: 19 dias | C16: 46253.375 | D16: 46279.75 | E16: 14II+3 dias
A17: Entrega no SITE 3º Lote | B17: 1 dia | C17: 46280.375 | D17: 46280.75 | E17: 15
A18: 4º Lote | B18: 23 dias | C18: 46255.375 | D18: 46287.75
A19: Spoletamento 4º Lote | B19: 5 dias | C19: 46255.375 | D19: 46261.75 | E19: 14
A20: Fabricação 3º Lote | B20: 10 dias | C20: 46273.375 | D20: 46286.75 | E20: 15TT+5 dias;18
A21: Entrega no SITE 4º Lote | B21: 1 dia | C21: 46287.375 | D21: 46287.75 | E21: 19

Sheet Histograma
C2: RESUMO DA FABRICAÇÃO DE TUBULAÇÃO | J2: 46230 | K2: =J2+7 -> 46237 | L2: =K2+7 -> 46244 | M2: =L2+7 -> 46251 | N2: =M2+7 -> 46258 | O2: =N2+7 -> 46265 | P2: =O2+7 -> 46272 | Q2: =P2+7 -> 46279 | R2: =Q2+7 -> 46286
E3: TUBO
B4: DESCRIÇÃO MAT. | C4: PESO (ton) | D4: TOTAL Hh | E4: IND. MED. PRODUT. Hh/t | G4: Ton. Sem. | H4: =AVERAGE(J4:R4) -> 2.9316196 | J4: =$C$6*J5 -> 1.5871826 | K4: =$C$6*K5 -> 2.7729014 | L4: =$C$6*L5 -> 3.4918017 | M4: =$C$6*M5 -> 3.6972018 | N4: =$C$6*N5 -> 3.6972018 | O4: =$C$6*O5 -> 3.4918017 | P4: =$C$6*P5 -> 3.2864016 | Q4: =$C$6*Q5 -> 2.7729014 | R4: =$C$6*R5 -> 1.5871826 | S4: =SUM(J4:R4) -> 26.384577
B5: AÇO CARBONO | INOX 304/304L | C5: 26.72 | D5: =C5*E5 -> 11447.706 | E5: 428.43212 | G5: Peso Total | H5: =C6 -> 26.72 | J5: =J6/$H$6 -> 0.059400546 | K5: =K6/$H$6 -> 0.10377625 | L5: =L6/$H$6 -> 0.1306812 | M5: =M6/$H$6 -> 0.13836833 | N5: =N6/$H$6 -> 0.13836833 | O5: =O6/$H$6 -> 0.1306812 | P5: =P6/$H$6 -> 0.12299407 | Q5: =Q6/$H$6 -> 0.10377625 | R5: =R6/$H$6 -> 0.059400546 | S5: =SUM(J5:R5) -> 0.98744673
B6: TOTAL | C6: =SUM(C4:C5) -> 26.72 | D6: =SUM(D4:D5) -> 11447.706 | E6: =SUM(E4:E5) -> 428.43212 | G6: Toal de Hh | H6: =D6 -> 11447.706 | J6: =J16*40 -> 680 | K6: =K16*44 -> 1188 | L6: =L16*44 -> 1496 | M6: =M16*44 -> 1584 | N6: =N16*44 -> 1584 | O6: =O16*44 -> 1496 | P6: =P16*44 -> 1408 | Q6: =Q16*44 -> 1188 | R6: =R16*40 -> 680 | S6: =SUM(J6:R6) -> 11304
G7: Descrição | H7: % | I7: Coeficiente | J7: Sem 1 | K7: Sem 2 | L7: Sem 3 | M7: Sem 4 | N7: Sem 5 | O7: Sem 6 | P7: Sem 7 | Q7: Sem 8 | R7: Sem 9 | S7: TOTAL
G8: ENCARREGADO(A) DE TUBULACAO | H8: =I8/100% -> 0.032787 | I8: 0.032787 | J8: =ROUNDUP($H$6*$H8/44/9,0) -> 1 | K8: =ROUNDUP($H$6*$H8/40/9,0) -> 2 | L8: =ROUNDUP($H$6*$H8/40/9,0) -> 2 | M8: =ROUNDUP($H$6*$H8/40/9,0) -> 2 | N8: =ROUNDUP($H$6*$H8/40/9,0) -> 2 | O8: =ROUNDUP($H$6*$H8/40/9,0) -> 2 | P8: =ROUNDUP($H$6*$H8/40/9,0) -> 2 | Q8: =ROUNDUP($H$6*$H8/40/9,0) -> 2 | R8: =ROUNDUP($H$6*$H8/44/9,0) -> 1 | S8: =MAX(J8:R8) -> 2
G9: ENCARREGADO(A) DE SOLDA | H9: =I9/100% -> 0.032787 | I9: 0.032787 | J9: =ROUNDUP($H$6*$H9/44/9,0) -> 1 | K9: =ROUNDUP($H$6*$H9/40/9,0) -> 2 | L9: =ROUNDUP($H$6*$H9/40/9,0) -> 2 | M9: =ROUNDUP($H$6*$H9/40/9,0) -> 2 | N9: =ROUNDUP($H$6*$H9/40/9,0) -> 2 | O9: =ROUNDUP($H$6*$H9/40/9,0) -> 2 | P9: =ROUNDUP($H$6*$H9/40/9,0) -> 2 | Q9: =ROUNDUP($H$6*$H9/40/9,0) -> 2 | R9: =ROUNDUP($H$6*$H9/44/9,0) -> 1 | S9: =MAX(J9:R9) -> 2
G10: ENCANADOR(A) INDUSTRIAL | H10: =I10/100% -> 0.262295 | I10: 0.262295 | J10: =ROUNDDOWN($H$6*$H10/70/9,0) -> 4 | K10: =ROUNDDOWN($H$6*$H10/50/9,0) -> 6 | L10: =ROUNDUP($H$6*$H10/40/9,0) -> 9 | M10: =ROUNDUP($H$6*$H10/35/9,0) -> 10 | N10: =ROUNDUP($H$6*$H10/35/9,0) -> 10 | O10: =ROUNDUP($H$6*$H10/40/9,0) -> 9 | P10: =ROUNDDOWN($H$6*$H10/40/9,0) -> 8 | Q10: =ROUNDDOWN($H$6*$H10/50/9,0) -> 6 | R10: =ROUNDDOWN($H$6*$H10/70/9,0) -> 4 | S10: =MAX(J10:R10) -> 10
G11: SOLDADOR(A) TIG/ER | H11: =I11/100% -> 0.262295 | I11: 0.262295 | J11: =ROUNDDOWN($H$6*$H11/70/9,0) -> 4 | K11: =ROUNDDOWN($H$6*$H11/50/9,0) -> 6 | L11: =ROUNDUP($H$6*$H11/40/9,0) -> 9 | M11: =ROUNDUP($H$6*$H11/35/9,0) -> 10 | N11: =ROUNDUP($H$6*$H11/35/9,0) -> 10 | O11: =ROUNDUP($H$6*$H11/40/9,0) -> 9 | P11: =ROUNDDOWN($H$6*$H11/40/9,0) -> 8 | Q11: =ROUNDDOWN($H$6*$H11/50/9,0) -> 6 | R11: =ROUNDDOWN($H$6*$H11/70/9,0) -> 4 | S11: =MAX(J11:R11) -> 10
G12: SOLDADOR(A) ER | H12: =I12/100% -> 0.065574 | I12: 0.065574 | J12: =ROUNDDOWN($H$6*$H12/44/9,0) -> 1 | K12: =ROUNDDOWN($H$6*$H12/60/9,0) -> 1 | L12: =ROUNDDOWN($H$6*$H12/60/9,0) -> 1 | M12: =ROUNDDOWN($H$6*$H12/60/9,0) -> 1 | N12: =ROUNDDOWN($H$6*$H12/60/9,0) -> 1 | O12: =ROUNDDOWN($H$6*$H12/60/9,0) -> 1 | P12: =ROUNDDOWN($H$6*$H12/60/9,0) -> 1 | Q12: =ROUNDDOWN($H$6*$H12/60/9,0) -> 1 | R12: =ROUNDDOWN($H$6*$H12/44/9,0) -> 1 | S12: =MAX(J12:R12) -> 1
G13: MACARIQUEIRO(A) | H13: =I13/100% -> 0.016393 | I13: 0.016393 | J13: =ROUNDUP($H$6*$H13/44/9,0) -> 1 | K13: =ROUNDUP($H$6*$H13/40/9,0) -> 1 | L13: =ROUNDUP($H$6*$H13/40/9,0) -> 1 | M13: =ROUNDUP($H$6*$H13/40/9,0) -> 1 | N13: =ROUNDUP($H$6*$H13/40/9,0) -> 1 | O13: =ROUNDUP($H$6*$H13/40/9,0) -> 1 | P13: =ROUNDUP($H$6*$H13/40/9,0) -> 1 | Q13: =ROUNDUP($H$6*$H13/40/9,0) -> 1 | R13: =ROUNDUP($H$6*$H13/44/9,0) -> 1 | S13: =MAX(J13:R13) -> 1
G14: LIXADOR(A) | H14: =I14/100% -> 0.196721 | I14: 0.196721 | J14: =ROUNDDOWN($H$6*$H14/70/9,0) -> 3 | K14: =ROUNDDOWN($H$6*$H14/40/9,0) -> 6 | L14: =ROUNDUP($H$6*$H14/40/9,0) -> 7 | M14: =ROUNDUP($H$6*$H14/40/9,0) -> 7 | N14: =ROUNDUP($H$6*$H14/40/9,0) -> 7 | O14: =ROUNDUP($H$6*$H14/40/9,0) -> 7 | P14: =ROUNDUP($H$6*$H14/40/9,0) -> 7 | Q14: =ROUNDDOWN($H$6*$H14/40/9,0) -> 6 | R14: =ROUNDDOWN($H$6*$H14/70/9,0) -> 3 | S14: =MAX(J14:R14) -> 7
G15: AJUDANTE DE PRODUCAO | H15: =I15/100% -> 0.131148 | I15: 0.131148 | J15: =ROUNDDOWN($H$6*$H15/70/9,0) -> 2 | K15: =ROUNDDOWN($H$6*$H15/44/9,0) -> 3 | L15: =ROUNDDOWN($H$6*$H15/44/9,0) -> 3 | M15: =ROUNDDOWN($H$6*$H15/44/9,0) -> 3 | N15: =ROUNDDOWN($H$6*$H15/44/9,0) -> 3 | O15: =ROUNDDOWN($H$6*$H15/44/9,0) -> 3 | P15: =ROUNDDOWN($H$6*$H15/44/9,0) -> 3 | Q15: =ROUNDDOWN($H$6*$H15/44/9,0) -> 3 | R15: =ROUNDDOWN($H$6*$H15/70/9,0) -> 2 | S15: =MAX(J15:R15) -> 3
G16: TOTAL | J16: =SUM(J8:J15) -> 17 | K16: =SUM(K8:K15) -> 27 | L16: =SUM(L8:L15) -> 34 | M16: =SUM(M8:M15) -> 36 | N16: =SUM(N8:N15) -> 36 | O16: =SUM(O8:O15) -> 34 | P16: =SUM(P8:P15) -> 32 | Q16: =SUM(Q8:Q15) -> 27 | R16: =SUM(R8:R15) -> 17

Sheet Analise de Lote
A1: Soma de FABRICAÇÃO ( KG ) | B1: Rótulos de Coluna
A2: Rótulos de Linha | B2: 17/ago | C2: 31/ago | D2: 15/set | E2: 22/set | F2: Total Geral
A3: 1º | B3: 6996.4534 | F3: 6996.4534
A4: CWP 3.1 - LIQUEFACTION | B4: 6996.4534 | F4: 6996.4534
A5: 2º | C5: 9936.88 | F5: 9936.88
A6: CWP 3.1 - LIQUEFACTION | C6: 9936.88 | F6: 9936.88
A7: 3º | D7: 7816.3839 | F7: 7816.3839
A8: CWP 1.1 - INLET GAS | D8: 4078.7946 | F8: 4078.7946
A9: CWP 2.1 - PRÉ-TREATMENT | D9: 3737.5893 | F9: 3737.5893
A10: 4º | E10: 1941.1313 | F10: 1941.1313
A11: CWP 4.1 - STORAGE TANKS | E11: 413.2217 | F11: 413.2217
A12: CWP 5.1 - E-HOUSES AREA | E12: 440.3334 | F12: 440.3334
A13: CWP 7.1 LOADING AREA | E13: 1087.5762 | F13: 1087.5762
A14: Total Geral | B14: 6996.4534 | C14: 9936.88 | D14: 7816.3839 | E14: 1941.1313 | F14: 26690.849

Sheet SEQ. DE ENTREGA POR LINHA
A1: ITEM | B1: LINHA | C1: SKID | D1: CWA | E1: FABRICAÇÃO ( KG ) | F1: FABRICAÇÃO ( Juntas ) | G1: DATA DE ENTREGA NO SITE PARA MONTAGEM | H1: LOTE
A2: 1 | B2: 1"-A1E-CF-4310A | C2: WASHING TOWER SKID A | D2: CWP 3.1 - LIQUEFACTION | E2: 18.05 | F2: 16 | G2: =VLOOKUP(C2,$C$188:$E$224,3,FALSE) -> 46251.75 | H2: =VLOOKUP(G2,$G$190:$H$193,2,FALSE) -> 1º
A3: 2 | B3: 1"-A3B-CWR-0612 | C3: COMPRESSOR | D3: CWP 1.1 - INLET GAS | E3: 19.2204 | F3: 8 | G3: =VLOOKUP(C3,$C$188:$E$224,3,FALSE) -> 46280.75 | H3: =VLOOKUP(G3,$G$190:$H$193,2,FALSE) -> 3º
A4: 3 | B4: 1"-B1E-MR-4005A | C4: COLD BOX A | D4: CWP 3.1 - LIQUEFACTION | E4: 2.625 | F4: 4 | G4: =VLOOKUP(C4,$C$188:$E$224,3,FALSE) -> 46251.75 | H4: =VLOOKUP(G4,$G$190:$H$193,2,FALSE) -> 1º
A5: 4 | B5: 1"-B1E-MR-4006A | C5: COLD BOX A | D5: CWP 3.1 - LIQUEFACTION | E5: 2.625 | F5: 4 | G5: =VLOOKUP(C5,$C$188:$E$224,3,FALSE) -> 46251.75 | H5: =VLOOKUP(G5,$G$190:$H$193,2,FALSE) -> 1º
A6: 5 | B6: 1"-B1E-MR-4007A | C6: COLD BOX A | D6: CWP 3.1 - LIQUEFACTION | E6: 2.625 | F6: 4 | G6: =VLOOKUP(C6,$C$188:$E$224,3,FALSE) -> 46251.75 | H6: =VLOOKUP(G6,$G$190:$H$193,2,FALSE) -> 1º
A7: 6 | B7: 1"-B1E-MR-4008A | C7: COLD BOX A | D7: CWP 3.1 - LIQUEFACTION | E7: 2.625 | F7: 4 | G7: =VLOOKUP(C7,$C$188:$E$224,3,FALSE) -> 46251.75 | H7: =VLOOKUP(G7,$G$190:$H$193,2,FALSE) -> 1º
A8: 7 | B8: 1"-B1E-MR-4009A | C8: COLD BOX A | D8: CWP 3.1 - LIQUEFACTION | E8: 2.625 | F8: 4 | G8: =VLOOKUP(C8,$C$188:$E$224,3,FALSE) -> 46251.75 | H8: =VLOOKUP(G8,$G$190:$H$193,2,FALSE) -> 1º
A9: 8 | B9: 1"-B3B-LO-5002A | C9: PIPERACK / MR LP COMPRESSOR SKID A | D9: CWP 3.1 - LIQUEFACTION | E9: 14.7698 | F9: 10 | G9: =VLOOKUP(C9,$C$188:$E$224,3,FALSE) -> 46265.75 | H9: =VLOOKUP(G9,$G$190:$H$193,2,FALSE) -> 2º
A10: 9 | B10: 1"-B3B-LO-5003A | C10: MR ACCUMULATION TANKS SKID | D10: CWP 3.1 - LIQUEFACTION | E10: 36.1224 | F10: 31 | G10: =VLOOKUP(C10,$C$188:$E$224,3,FALSE) -> 46251.75 | H10: =VLOOKUP(G10,$G$190:$H$193,2,FALSE) -> 1º
A11: 10 | B11: 1"-B3B-LO-5004A | C11: PIPERACK / MR LP COMPRESSOR SKID A | D11: CWP 3.1 - LIQUEFACTION | E11: 35.0486 | F11: 12 | G11: =VLOOKUP(C11,$C$188:$E$224,3,FALSE) -> 46265.75 | H11: =VLOOKUP(G11,$G$190:$H$193,2,FALSE) -> 2º
A12: 11 | B12: 1"-B3B-LPG-LIT-7301A | C12: MIXED HYDROCARBON TANK | D12: CWP 2.1 - PRÉ-TREATMENT | E12: 3.124 | F12: 2 | G12: =VLOOKUP(C12,$C$188:$E$224,3,FALSE) -> 46280.75 | H12: =VLOOKUP(G12,$G$190:$H$193,2,FALSE) -> 3º
A13: 12 | B13: 1"-B3B-LPG-LIT-7301B | C13: MIXED HYDROCARBON TANK | D13: CWP 2.1 - PRÉ-TREATMENT | E13: 3.124 | F13: 2 | G13: =VLOOKUP(C13,$C$188:$E$224,3,FALSE) -> 46280.75 | H13: =VLOOKUP(G13,$G$190:$H$193,2,FALSE) -> 3º
... A179: 178 | B179: 3"-A3B-HM-8201-H-3'' | C179: HOT OIL | D179: CWP 1.1 - INLET GAS | E179: 231.89412 | F179: 13 | G179: =VLOOKUP(C179,$C$188:$E$224,3,FALSE) -> 46280.75 | H179: =VLOOKUP(G179,$G$190:$H$193,2,FALSE) -> 3º
C188: CWP | D188: DATA MILPLAN CORRENTE SEMANA 44 | E188: DATA NECESSIDADE INTERNA PARA PROPONENTE
C189: CWP 1.1 - INLET GAS | G189: DATA | H189: LOTE
C190: COMPRESSOR | D190: 46288 | E190: =G192 -> 46280.75 | G190: =Cronograma!D6 -> 46251.75 | H190: 1º
C191: HOT OIL | D191: 46281 | E191: =E190 -> 46280.75 | G191: =Cronograma!D10 -> 46265.75 | H191: 2º
C192: PIPE RACK / DISCHARGE SEPARATION TANK | D192: 46297 | E192: =E191 -> 46280.75 | G192: =Cronograma!D14 -> 46280.75 | H192: 3º
C193: EAG HEATER / DISCHARGE SEPARATION TANK | D193: 46322 | E193: =E192 -> 46280.75 | G193: =Cronograma!D18 -> 46287.75 | H193: 4º
C194: EAG HEATER / PIPE RACK | D194: 46308 | E194: =E193 -> 46280.75
C195: CWP 2.1 - PRÉ-TREATMENT
C196: DEACIDIFICATION A | D196: 46246 | E196: =G192 -> 46280.75
C197: DEACIDIFICATION B | D197: 46261 | E197: =E196 -> 46280.75
C198: DEHYDRATION C | D198: 46290 | E198: =E197 -> 46280.75
C199: DEHYDRATION D | D199: 46308 | E199: =E198 -> 46280.75
C200: MIXED HYDROCARBON TANK | D200: 46283 | E200: =E199 -> 46280.75
C201: CWP 3.1 - LIQUEFACTION
C202: PIPERACK / MR LP COMPRESSOR SKID A | D202: 46279 | E202: =G191 -> 46265.75
C203: PIPE RACK / MR LP COMPRESSOR SKID B | D203: 46283 | E203: =E202 -> 46265.75
C204: PIPE RACK / MR HP COMPRESSOR SKID A | D204: 46295 | E204: =E203 -> 46265.75
C205: PIPE RACK / MR HP COMPRESSOR SKID B | D205: 46279 | E205: =E204 -> 46265.75
C206: MR ACCUMULATION TANKS SKID | D206: 46286 | E206: =G190 -> 46251.75
C207: COLD BOX A | D207: 46280 | E207: =E206 -> 46251.75
C208: WASHING TOWER SKID A | D208: 46283 | E208: =E207 -> 46251.75
C209: CWP 4.1 - STORAGE TANKS
C210: PIPE RACK | D210: 46276 | E210: =G193 -> 46287.75
C211: LNG TANK A | D211: 46287 | E211: =E210 -> 46287.75
C212: LNG TANK B | D212: 46289 | E212: =E211 -> 46287.75
C213: LNG TANK C | D213: 46293 | E213: =E212 -> 46287.75
...

Sheet Crono Furui
A1: CRONOGRAMA 21/08/2026
A2: EDT | B2: Modo da Tarefa | C2: Nome da Tarefa | D2: % concluída | E2: Duração | F2: Início | G2: Término
A3: 1 | B3: Agendada Manualmente | C3: CRONOGRAMA BRASNAVAL | D3: 0.44 | E3: 52 dias | F3: 46241.292 | G3: 46287.375
A4: 1.1 | B4: Agendada Manualmente | C4: MATÉRIA PRIMA | D4: 0.44 | E4: 5 dias | F4: 46241.292 | G4: 46245.458
A5: 1.1.1 | B5: Agendada Automaticamente | C5: Recebimento da matéria prima | D5: 1 | E5: 1 dia | F5: 46241.292 | G5: 46241.667
A6: 1.1.2 | B6: Agendada Automaticamente | C6: Conferência do material | D6: 0 | E6: 4 dias | F6: 46241.292 | G6: 46245.458
A7: 1.1.3 | B7: Agendada Manualmente | C7: Fabricação dos lote 1-2-3 e 4 | D7: 0 | E7: 45 dias | F7: 46248.292 | G7: 46287.708
A8: 1.1.3.1 | B8: Agendada Manualmente | C8: Fabricação lote 1 | D8: 0 | E8: 11 dias | F8: 46248.292 | G8: 46257.625
A9: 1.1.4 | B9: Agendada Manualmente | C9: 1"-A1E-CF-4310A | D9: 1 | E9: 2 dias | F9: 46245.458 | G9: 46247.375
A10: 2 | B10: Agendada Manualmente | C10: 1"-B1E-MR-4005A | D10: 0.6 | E10: 1 dia | F10: 46246.667 | G10: 46247.625
A11: 2.8 | B11: Agendada Manualmente | C11: 1"-B1E-MR-4006A | D11: 0.58 | E11: 1 dia | F11: 46249.625 | G11: 46250.583
A12: 2.8.2 | B12: Agendada Automaticamente | C12: 1"-B1E-MR-4007A | D12: 1 | E12: 1 dia | F12: 46249.625 | G12: 46250.583
A13: 2.8.3 | B13: Agendada Automaticamente | C13: 1"-B1E-MR-4008A | D13: 1 | E13: 1 dia | F13: 46249.625 | G13: 46250.583
A14: 2.8.4 | B14: Agendada Automaticamente | C14: 1"-B1E-MR-4009A | D14: 1 | E14: 1 dia | F14: 46249.625 | G14: 46250.583
A15: 2.8.5 | B15: Agendada Automaticamente | C15: 1"-B3B-LO-5003A | D15: 1 | E15: 1 dia | F15: 46249.625 | G15: 46250.583
A16: 2.8.6 | B16: Agendada Automaticamente | C16: 1"-D1E-LPG-4305A-C-3" | D16: 1 | E16: 1 dia | F16: 46249.625 | G16: 46250.583
A17: 2.8.7 | B17: Agendada Automaticamente | C17: 1"-D1E-LPG-4308A-C-3" | D17: 1 | E17: 1 dia | F17: 46249.625 | G17: 46250.583
A18: 2.8.8 | B18: Agendada Automaticamente | C18: 1"-D1E-NG-4001A | D18: 1 | E18: 1 dia | F18: 46249.625 | G18: 46250.583
A19: 2.8.9 | B19: Agendada Automaticamente | C19: 1"-D3B-NG-3105A | D19: 1 | E19: 1 dia | F19: 46249.625 | G19: 46250.583
A20: 2.8.10 | B20: Agendada Automaticamente | C20: 2"-A1E-CF-4007A | D20: 1 | E20: 1 dia | F20: 46250.583 | G20: 46251.5
A21: 2.8.11 | B21: Agendada Automaticamente | C21: 2"-B1E-MR-4010A | D21: 1 | E21: 1 dia | F21: 46250.583 | G21: 46251.5
A22: 2.8.12 | B22: Agendada Automaticamente | C22: 2"-D1E-LPG-4002A-C-3" | D22: 1 | E22: 1 dia | F22: 46250.583 | G22: 46251.5
... A39: 2.8.27 | B39: Agendada Automaticamente | C39: 2"-A1E-IA-9011 | D39: 0 | E39: 1 dia | F39: 46256.667 | G39: 46257.625
A40: 3 | B40: Agendada Manualmente | C40: Fabricação lote 2 | D40: 0 | E40: 10 dias | F40: 46258.292 | G40: 46266.667
A41: 3.1 | B41: Agendada Manualmente | C41: 1"-B3B-LO-5002A | D41: 0 | E41: 2 dias | F41: 46258.292 | G41: 46259.625
A42: 4 | B42: Agendada Manualmente | C42: 1"-B3B-LO-5004A | D42: 0 | E42: 2 dias | F42: 46258.292 | G42: 46259.625
A43: 4.8 | B43: Agendada Manualmente | C43: 10"-B3B-MR-5203A-PP-2" | D43: 0 | E43: 2 dias | F43: 46259.292 | G43: 46260.625
A44: 4.8.8 | B44: Agendada Automaticamente | C44: 10"-B3B-MR-5203B-PP-2" | D44: 0 | E44: 1 dia | F44: 46259.667 | G44: 46260.625
A45: 4.8.9 | B45: Agendada Automaticamente | C45: 16"-B3B-MR-5001A | D45: 0 | E45: 1 dia | F45: 46259.667 | G45: 46260.625
A46: 4.8.10 | B46: Agendada Automaticamente | C46: 16"-B3B-MR-5002A | D46: 0 | E46: 1 dia | F46: 46259.667 | G46: 46260.625
A47: 4.8.11 | B47: Agendada Automaticamente | C47: 3"-B3B-MR-5305B | D47: 0 | E47: 1 dia | F47: 46259.667 | G47: 46260.625
A48: 4.8.12 | B48: Agendada Automaticamente | C48: 3"-B3B-MR-5505A | D48: 0 | E48: 1 dia | F48: 46259.667 | G48: 46260.625
A49: 4.8.13 | B49: Agendada Automaticamente | C49: 4"-B3B-MR-5511A | D49: 0 | E49: 1 dia | F49: 46260.625 | G49: 46261.583
A50: 4.8.14 | B50: Agendada Automaticamente | C50: 4"-B3B-MR-5511B | D50: 0 | E50: 1 dia | F50: 46260.625 | G50: 46261.583
A51: 4.8.15 | B51: Agendada Automaticamente | C51: 6"-A3B-HF-5503A | D51: 0 | E51: 1 dia | F51: 46260.625 | G51: 46261.583
A52: 4.8.16 | B52: Agendada Automaticamente | C52: 6"-A3B-HF-5503B | D52: 0 | E52: 1 dia | F52: 46260.625 | G52: 46261.583
A53: 4.8.17 | B53: Agendada Automaticamente | C53: 6"-B3B-MR-5503A | D53: 0 | E53: 1 dia | F53: 46261.583 | G53: 46262.5
A54: 4.8.18 | B54: Agendada Automaticamente | C54: 6"-B3B-MR-5503B | D54: 0 | E54: 1 dia | F54: 46261.583 | G54: 46262.5
... A189: 4.8.50.26 | B189: Agendada Manualmente | C189: 3"-A1E-BOG-7009-C-2" | D189: 0 | E189: 1 dia | F189: 46280.292 | G189: 46280.667

Sheet Analise Cronograma TUB
K1: CRONOGRAMA 21/08/2026 | P1: CALCULO DO AVANÇO PREVISTO
K2: DATA MAXIMA POR LOTE PREVISTO LB | O2: PERCENTUAL DE AVANÇO REAL PONDERADO PELO PESO ACUM. | Q2: =R3-P3 -> 14 | R2: =Q3-P3 -> 4 | S2: =R2/Q2 -> 0.28571429
K3: 1º | L3: 2º | M3: 3º | N3: 4º | P3: 46251 | Q3: 46255 | R3: 46265
K4: =_xlfn.MAXIFS($H$9:$H$186,$I$9:$I$186,K3) -> 46251.75 | L4: =_xlfn.MAXIFS($H$9:$H$186,$I$9:$I$186,L3) -> 46265.75 | M4: =_xlfn.MAXIFS($H$9:$H$186,$I$9:$I$186,M3) -> 46280.75 | N4: =_xlfn.MAXIFS($H$9:$H$186,$I$9:$I$186,N3) -> 46287.75 | O4: =S6 -> 0.36849941 | P4: =SUMIFS(F9:F186,I9:I186,K3) -> 6996.4534 | Q4: =R4*S2 -> 2839.1086 | R4: =SUMIFS(F9:F186,I9:I186,L3) -> 9936.88
K5: DATA MAXIMA POR LOTE NO CRONOGRAMA | O5: PERCENTUAL DE AVANÇO REAL PONDERADO PELO PESO ACUM. | R5: =SUM(F9:F186) -> 26690.849
K6: 1º | L6: 2º | M6: 3º | N6: 4º | R6: =P4+Q4 -> 9835.5619 | S6: =R6/R5 -> 0.36849941
K7: =_xlfn.MAXIFS($M$9:$M$186,$I$9:$I$186,K6) -> 46257.625 | L7: =_xlfn.MAXIFS($M$9:$M$186,$I$9:$I$186,L6) -> 46267.667 | M7: =_xlfn.MAXIFS($M$9:$M$186,$I$9:$I$186,M6) -> 46279.5 | N7: =_xlfn.MAXIFS($M$9:$M$186,$I$9:$I$186,N6) -> 46286.375
A8: ITEM | B8: TAG PADRONIZADA | C8: LINHA | D8: SKID | E8: CWA | F8: FABRICAÇÃO ( KG ) | G8: FABRICAÇÃO ( Juntas ) | H8: DATA DE ENTREGA NO SITE PARA MONTAGEM | I8: LOTE | J8: DATA REAL RECEBIMENTO SITE | K8: TESTE ESCOPO | L8: STATUS DE FABRICAÇÃO | M8: DATA DE TÉRMINO CRONOGRAMA | N8: TESTE SE A DATA ATENDE A NECESSIDADE | O8: =SUM(O9:O186)/SUM(F9:F186) -> 0.12682671 | P8: VERIFICAÇÃO DA INFO
A9: 1 | B9: 1"-A1E-CF-4310A | C9: 1"-A1E-CF-4310A | D9: WASHING TOWER SKID A | E9: CWP 3.1 - LIQUEFACTION | F9: 18.05 | G9: 16 | H9: =VLOOKUP(D9,$D$195:$F$231,3,FALSE) -> 46251.75 | I9: =VLOOKUP(H9,$H$197:$I$200,2,FALSE) -> 1º | J9: 46254 | K9: =IF(VLOOKUP(C9,'Crono Furui'!$C$2:$C$189,1,FALSE)="","VERIFICAR","OK") -> OK | L9: =VLOOKUP(C9,'Crono Furui'!$C:$G,2,FALSE) -> 1 | M9: =VLOOKUP(C9,'Crono Furui'!$C:$G,5,FALSE) -> 46247.375 | N9: =IF(M9>H9=FALSE,"ATENDE",ROUNDUP(M9-H9,0)) -> ATENDE | O9: =L9*F9 -> 18.05
A10: 2 | B10: 1"-A3B-CWR-0612 | C10: 1"-A3B-CWR-0612 | D10: COMPRESSOR | E10: CWP 1.1 - INLET GAS | F10: 19.2204 | G10: 8 | H10: =VLOOKUP(D10,$D$195:$F$231,3,FALSE) -> 46280.75 | I10: =VLOOKUP(H10,$H$197:$I$200,2,FALSE) -> 3º | K10: =IF(VLOOKUP(C10,'Crono Furui'!$C$2:$C$189,1,FALSE)="","VERIFICAR","OK") -> OK | L10: =VLOOKUP(C10,'Crono Furui'!$C:$G,2,FALSE) -> 0 | M10: =VLOOKUP(C10,'Crono Furui'!$C:$G,5,FALSE) -> 46267.667 | N10: =IF(M10>H10=FALSE,"ATENDE",ROUNDUP(M10-H10,0)) -> ATENDE | O10: =L10*F10 -> 0
A11: 3 | B11: 1"-B1E-MR-4005A | C11: 1"-B1E-MR-4005A | D11: COLD BOX A | E11: CWP 3.1 - LIQUEFACTION | F11: 2.625 | G11: 4 | H11: =VLOOKUP(D11,$D$195:$F$231,3,FALSE) -> 46251.75 | I11: =VLOOKUP(H11,$H$197:$I$200,2,FALSE) -> 1º | J11: 46254 | K11: =IF(VLOOKUP(C11,'Crono Furui'!$C$2:$C$189,1,FALSE)="","VERIFICAR","OK") -> OK | L11: =VLOOKUP(C11,'Crono Furui'!$C:$G,2,FALSE) -> 0.6 | M11: =VLOOKUP(C11,'Crono Furui'!$C:$G,5,FALSE) -> 46247.625 | N11: =IF(M11>H11=FALSE,"ATENDE",ROUNDUP(M11-H11,0)) -> ATENDE | O11: =L11*F11 -> 1.575
A12: 4 | B12: 1"-B1E-MR-4006A | C12: 1"-B1E-MR-4006A | D12: COLD BOX A | E12: CWP 3.1 - LIQUEFACTION | F12: 2.625 | G12: 4 | H12: =VLOOKUP(D12,$D$195:$F$231,3,FALSE) -> 46251.75 | I12: =VLOOKUP(H12,$H$197:$I$200,2,FALSE) -> 1º | J12: 46254 | K12: =IF(VLOOKUP(C12,'Crono Furui'!$C$2:$C$189,1,FALSE)="","VERIFICAR","OK") -> OK | L12: =VLOOKUP(C12,'Crono Furui'!$C:$G,2,FALSE) -> 0.58 | M12: =VLOOKUP(C12,'Crono Furui'!$C:$G,5,FALSE) -> 46250.583 | N12: =IF(M12>H12=FALSE,"ATENDE",ROUNDUP(M12-H12,0)) -> ATENDE | O12: =L12*F12 -> 1.5225
A13: 5 | B13: 1"-B1E-MR-4007A | C13: 1"-B1E-MR-4007A | D13: COLD BOX A | E13: CWP 3.1 - LIQUEFACTION | F13: 2.625 | G13: 4 | H13: =VLOOKUP(D13,$D$195:$F$231,3,FALSE) -> 46251.75 | I13: =VLOOKUP(H13,$H$197:$I$200,2,FALSE) -> 1º | J13: 46254 | K13: =IF(VLOOKUP(C13,'Crono Furui'!$C$2:$C$189,1,FALSE)="","VERIFICAR","OK") -> OK | L13: =VLOOKUP(C13,'Crono Furui'!$C:$G,2,FALSE) -> 1 | M13: =VLOOKUP(C13,'Crono Furui'!$C:$G,5,FALSE) -> 46250.583 | N13: =IF(M13>H13=FALSE,"ATENDE",ROUNDUP(M13-H13,0)) -> ATENDE | O13: =L13*F13 -> 2.625
A14: 6 | B14: 1"-B1E-MR-4008A | C14: 1"-B1E-MR-4008A | D14: COLD BOX A | E14: CWP 3.1 - LIQUEFACTION | F14: 2.625 | G14: 4 | H14: =VLOOKUP(D14,$D$195:$F$231,3,FALSE) -> 46251.75 | I14: =VLOOKUP(H14,$H$197:$I$200,2,FALSE) -> 1º | J14: 46254 | K14: =IF(VLOOKUP(C14,'Crono Furui'!$C$2:$C$189,1,FALSE)="","VERIFICAR","OK") -> OK | L14: =VLOOKUP(C14,'Crono Furui'!$C:$G,2,FALSE) -> 1 | M14: =VLOOKUP(C14,'Crono Furui'!$C:$G,5,FALSE) -> 46250.583 | N14: =IF(M14>H14=FALSE,"ATENDE",ROUNDUP(M14-H14,0)) -> ATENDE | O14: =L14*F14 -> 2.625
A15: 7 | B15: 1"-B1E-MR-4009A | C15: 1"-B1E-MR-4009A | D15: COLD BOX A | E15: CWP 3.1 - LIQUEFACTION | F15: 2.625 | G15: 4 | H15: =VLOOKUP(D15,$D$195:$F$231,3,FALSE) -> 46251.75 | I15: =VLOOKUP(H15,$H$197:$I$200,2,FALSE) -> 1º | J15: 46254 | K15: =IF(VLOOKUP(C15,'Crono Furui'!$C$2:$C$189,1,FALSE)="","VERIFICAR","OK") -> OK | L15: =VLOOKUP(C15,'Crono Furui'!$C:$G,2,FALSE) -> 1 | M15: =VLOOKUP(C15,'Crono Furui'!$C:$G,5,FALSE) -> 46250.583 | N15: =IF(M15>H15=FALSE,"ATENDE",ROUNDUP(M15-H15,0)) -> ATENDE | O15: =L15*F15 -> 2.625
A16: 8 | B16: 1"-B3B-LO-5002A | C16: 1"-B3B-LO-5002A | D16: PIPERACK / MR LP COMPRESSOR SKID A | E16: CWP 3.1 - LIQUEFACTION | F16: 14.7698 | G16: 10 | H16: =VLOOKUP(D16,$D$195:$F$231,3,FALSE) -> 46265.75 | I16: =VLOOKUP(H16,$H$197:$I$200,2,FALSE) -> 2º | K16: =IF(VLOOKUP(C16,'Crono Furui'!$C$2:$C$189,1,FALSE)="","VERIFICAR","OK") -> OK | L16: =VLOOKUP(C16,'Crono Furui'!$C:$G,2,FALSE) -> 0 | M16: =VLOOKUP(C16,'Crono Furui'!$C:$G,5,FALSE) -> 46259.625 | N16: =IF(M16>H16=FALSE,"ATENDE",ROUNDUP(M16-H16,0)) -> ATENDE | O16: =L16*F16 -> 0
A17: 9 | B17: 1"-B3B-LO-5003A | C17: 1"-B3B-LO-5003A | D17: MR ACCUMULATION TANKS SKID | E17: CWP 3.1 - LIQUEFACTION | F17: 36.1224 | G17: 31 | H17: =VLOOKUP(D17,$D$195:$F$231,3,FALSE) -> 46251.75 | I17: =VLOOKUP(H17,$H$197:$I$200,2,FALSE) -> 1º | J17: 46254 | K17: =IF(VLOOKUP(C17,'Crono Furui'!$C$2:$C$189,1,FALSE)="","VERIFICAR","OK") -> OK | L17: =VLOOKUP(C17,'Crono Furui'!$C:$G,2,FALSE) -> 1 | M17: =VLOOKUP(C17,'Crono Furui'!$C:$G,5,FALSE) -> 46250.583 | N17: =IF(M17>H17=FALSE,"ATENDE",ROUNDUP(M17-H17,0)) -> ATENDE | O17: =L17*F17 -> 36.1224
A18: 10 | B18: 1"-B3B-LO-5004A | C18: 1"-B3B-LO-5004A | D18: PIPERACK / MR LP COMPRESSOR SKID A | E18: CWP 3.1 - LIQUEFACTION | F18: 35.0486 | G18: 12 | H18: =VLOOKUP(D18,$D$195:$F$231,3,FALSE) -> 46265.75 | I18: =VLOOKUP(H18,$H$197:$I$200,2,FALSE) -> 2º | K18: =IF(VLOOKUP(C18,'Crono Furui'!$C$2:$C$189,1,FALSE)="","VERIFICAR","OK") -> OK | L18: =VLOOKUP(C18,'Crono Furui'!$C:$G,2,FALSE) -> 0 | M18: =VLOOKUP(C18,'Crono Furui'!$C:$G,5,FALSE) -> 46259.625 | N18: =IF(M18>H18=FALSE,"ATENDE",ROUNDUP(M18-H18,0)) -> ATENDE | O18: =L18*F18 -> 0
A19: 11 | B19: 1"-B3B-LPG-LIT7301A | C19: 1"-B3B-LPG-LIT-7301A | D19: MIXED HYDROCARBON TANK | E19: CWP 2.1 - PRÉ-TREATMENT | F19: 3.124 | G19: 2 | H19: =VLOOKUP(D19,$D$195:$F$231,3,FALSE) -> 46280.75 | I19: =VLOOKUP(H19,$H$197:$I$200,2,FALSE) -> 3º | K19: =IF(VLOOKUP(C19,'Crono Furui'!$C$2:$C$189,1,FALSE)="","VERIFICAR","OK") -> OK | L19: =VLOOKUP(C19,'Crono Furui'!$C:$G,2,FALSE) -> 0 | M19: =VLOOKUP(C19,'Crono Furui'!$C:$G,5,FALSE) -> 46268.667 | N19: =IF(M19>H19=FALSE,"ATENDE",ROUNDUP(M19-H19,0)) -> ATENDE | O19: =L19*F19 -> 0
A20: 12 | B20: 1"-B3B-LPG-LIT7301B | C20: 1"-B3B-LPG-LIT-7301B | D20: MIXED HYDROCARBON TANK | E20: CWP 2.1 - PRÉ-TREATMENT | F20: 3.124 | G20: 2 | H20: =VLOOKUP(D20,$D$195:$F$231,3,FALSE) -> 46280.75 | I20: =VLOOKUP(H20,$H$197:$I$200,2,FALSE) -> 3º | K20: =IF(VLOOKUP(C20,'Crono Furui'!$C$2:$C$189,1,FALSE)="","VERIFICAR","OK") -> OK | L20: =VLOOKUP(C20,'Crono Furui'!$C:$G,2,FALSE) -> 0 | M20: =VLOOKUP(C20,'Crono Furui'!$C:$G,5,FALSE) -> 46268.667 | N20: =IF(M20>H20=FALSE,"ATENDE",ROUNDUP(M20-H20,0)) -> ATENDE | O20: =L20*F20 -> 0
A21: 13 | B21: 1"-D1E-LPG-4305A | C21: 1"-D1E-LPG-4305A-C-3" | D21: COLD BOX A | E21: CWP 3.1 - LIQUEFACTION | F21: 17.1972 | G21: 8 | H21: =VLOOKUP(D21,$D$195:$F$231,3,FALSE) -> 46251.75 | I21: =VLOOKUP(H21,$H$197:$I$200,2,FALSE) -> 1º | J21: 46254 | K21: =IF(VLOOKUP(C21,'Crono Furui'!$C$2:$C$189,1,FALSE)="","VERIFICAR","OK") -> OK | L21: =VLOOKUP(C21,'Crono Furui'!$C:$G,2,FALSE) -> 1 | M21: =VLOOKUP(C21,'Crono Furui'!$C:$G,5,FALSE) -> 46250.583 | N21: =IF(M21>H21=FALSE,"ATENDE",ROUNDUP(M21-H21,0)) -> ATENDE | O21: =L21*F21 -> 17.1972
A22: 14 | B22: 1"-D1E-LPG-4308A | C22: 1"-D1E-LPG-4308A-C-3" | D22: WASHING TOWER SKID A | E22: CWP 3.1 - LIQUEFACTION | F22: 28.1448 | G22: 10 | H22: =VLOOKUP(D22,$D$195:$F$231,3,FALSE) -> 46251.75 | I22: =VLOOKUP(H22,$H$197:$I$200,2,FALSE) -> 1º | J22: 46254 | K22: =IF(VLOOKUP(C22,'Crono Furui'!$C$2:$C$189,1,FALSE)="","VERIFICAR","OK") -> OK | L22: =VLOOKUP(C22,'Crono Furui'!$C:$G,2,FALSE) -> 1 | M22: =VLOOKUP(C22,'Crono Furui'!$C:$G,5,FALSE) -> 46250.583 | N22: =IF(M22>H22=FALSE,"ATENDE",ROUNDUP(M22-H22,0)) -> ATENDE | O22: =L22*F22 -> 28.1448
A23: 15 | B23: 1"-D1E-NG-4001A | C23: 1"-D1E-NG-4001A | D23: COLD BOX A | E23: CWP 3.1 - LIQUEFACTION | F23: 43.1928 | G23: 22 | H23: =VLOOKUP(D23,$D$195:$F$231,3,FALSE) -> 46251.75 | I23: =VLOOKUP(H23,$H$197:$I$200,2,FALSE) -> 1º | J23: 46254 | K23: =IF(VLOOKUP(C23,'Crono Furui'!$C$2:$C$189,1,FALSE)="","VERIFICAR","OK") -> OK | L23: =VLOOKUP(C23,'Crono Furui'!$C:$G,2,FALSE) -> 1 | M23: =VLOOKUP(C23,'Crono Furui'!$C:$G,5,FALSE) -> 46250.583 | N23: =IF(M23>H23=FALSE,"ATENDE",ROUNDUP(M23-H23,0)) -> ATENDE | O23: =L23*F23 -> 43.1928
A24: 16 | B24: 1"-D3B-NG-3105A | C24: 1"-D3B-NG-3105A | D24: MR ACCUMULATION TANKS SKID | E24: CWP 3.1 - LIQUEFACTION | F24: 22.364 | G24: 24 | H24: =VLOOKUP(D24,$D$195:$F$231,3,FALSE) -> 46251.75 | I24: =VLOOKUP(H24,$H$197:$I$200,2,FALSE) -> 1º | J24: xx | K24: =IF(VLOOKUP(C24,'Crono Furui'!$C$2:$C$189,1,FALSE)="","VERIFICAR","OK") -> OK | L24: =VLOOKUP(C24,'Crono Furui'!$C:$G,2,FALSE) -> 1 | M24: =VLOOKUP(C24,'Crono Furui'!$C:$G,5,FALSE) -> 46250.583 | N24: =IF(M24>H24=FALSE,"ATENDE",ROUNDUP(M24-H24,0)) -> ATENDE | O24: =L24*F24 -> 22.364 | P24: INFO INCOERENTE
A25: 17 | B25: 1.1/2"-A3B-CWR-0609 | C25: 1.1/2"-A3B-CWR-0609 | D25: COMPRESSOR | E25: CWP 1.1 - INLET GAS | F25: 18 | G25: 16 | H25: =VLOOKUP(D25,$D$195:$F$231,3,FALSE) -> 46280.75 | I25: =VLOOKUP(H25,$H$197:$I$200,2,FALSE) -> 3º | K25: =IF(VLOOKUP(C25,'Crono Furui'!$C$2:$C$189,1,FALSE)="","VERIFICAR","OK") -> OK | L25: =VLOOKUP(C25,'Crono Furui'!$C:$G,2,FALSE) -> 0 | M25: =VLOOKUP(C25,'Crono Furui'!$C:$G,5,FALSE) -> 46268.667 | N25: =IF(M25>H25=FALSE,"ATENDE",ROUNDUP(M25-H25,0)) -> ATENDE | O25: =L25*F25 -> 0
A26: 18 | B26: 1.1/2"-A3B-CWS-0601 | C26: 1.1/2"-A3B-CWS-0601 | D26: COMPRESSOR | E26: CWP 1.1 - INLET GAS | F26: 18 | G26: 16 | H26: =VLOOKUP(D26,$D$195:$F$231,3,FALSE) -> 46280.75 | I26: =VLOOKUP(H26,$H$197:$I$200,2,FALSE) -> 3º | K26: =IF(VLOOKUP(C26,'Crono Furui'!$C$2:$C$189,1,FALSE)="","VERIFICAR","OK") -> OK | L26: =VLOOKUP(C26,'Crono Furui'!$C:$G,2,FALSE) -> 0 | M26: =VLOOKUP(C26,'Crono Furui'!$C:$G,5,FALSE) -> 46268.667 | N26: =IF(M26>H26=FALSE,"ATENDE",ROUNDUP(M26-H26,0)) -> ATENDE | O26: =L26*F26 -> 0
A27: 19 | B27: 1/2"-A3B-CWS-0607 | C27: 1/2"-A3B-CWS-0607 | D27: COMPRESSOR | E27: CWP 1.1 - INLET GAS | F27: 8 | G27: 6 | H27: =VLOOKUP(D27,$D$195:$F$231,3,FALSE) -> 46280.75 | I27: =VLOOKUP(H27,$H$197:$I$200,2,FALSE) -> 3º | K27: =IF(VLOOKUP(C27,'Crono Furui'!$C$2:$C$189,1,FALSE)="","VERIFICAR","OK") -> OK | L27: =VLOOKUP(C27,'Crono Furui'!$C:$G,2,FALSE) -> 0 | M27: =VLOOKUP(C27,'Crono Furui'!$C:$G,5,FALSE) -> 46268.667 | N27: =IF(M27>H27=FALSE,"ATENDE",ROUNDUP(M27-H27,0)) -> ATENDE | O27: =L27*F27 -> 0
A28: 20 | B28: 1/2"-A3B-CWS-0608 | C28: 1/2"-A3B-CWS-0608 | D28: COMPRESSOR | E28: CWP 1.1 - INLET GAS | F28: 8 | G28: 8 | H28: =VLOOKUP(D28,$D$195:$F$231,3,FALSE) -> 46280.75 | I28: =VLOOKUP(H28,$H$197:$I$200,2,FALSE) -> 3º | K28: =IF(VLOOKUP(C28,'Crono Furui'!$C$2:$C$189,1,FALSE)="","VERIFICAR","OK") -> OK | L28: =VLOOKUP(C28,'Crono Furui'!$C:$G,2,FALSE) -> 0 | M28: =VLOOKUP(C28,'Crono Furui'!$C:$G,5,FALSE) -> 46268.667 | N28: =IF(M28>H28=FALSE,"ATENDE",ROUNDUP(M28-H28,0)) -> ATENDE | O28: =L28*F28 -> 0
A29: 21 | B29: 10"-A3B-HF-9301 | C29: 10"-A3B-HF-9301 | D29: PIPE RACK / DISCHARGE SEPARATION TANK | E29: CWP 1.1 - INLET GAS | F29: 565.3976 | G29: 53 | H29: =VLOOKUP(D29,$D$195:$F$231,3,FALSE) -> 46280.75 | I29: =VLOOKUP(H29,$H$197:$I$200,2,FALSE) -> 3º | K29: =IF(VLOOKUP(C29,'Crono Furui'!$C$2:$C$189,1,FALSE)="","VERIFICAR","OK") -> OK | L29: =VLOOKUP(C29,'Crono Furui'!$C:$G,2,FALSE) -> 0 | M29: =VLOOKUP(C29,'Crono Furui'!$C:$G,5,FALSE) -> 46268.667 | N29: =IF(M29>H29=FALSE,"ATENDE",ROUNDUP(M29-H29,0)) -> ATENDE | O29: =L29*F29 -> 0
A30: 22 | B30: 10"-A3B-HF-9401 | C30: 10"-A3B-HF-9401 | D30: PIPE RACK / DISCHARGE SEPARATION TANK | E30: CWP 1.1 - INLET GAS | F30: 168.9113 | G30: 23 | H30: =VLOOKUP(D30,$D$195:$F$231,3,FALSE) -> 46280.75 | I30: =VLOOKUP(H30,$H$197:$I$200,2,FALSE) -> 3º | K30: =IF(VLOOKUP(C30,'Crono Furui'!$C$2:$C$189,1,FALSE)="","VERIFICAR","OK") -> OK | L30: =VLOOKUP(C30,'Crono Furui'!$C:$G,2,FALSE) -> 0 | M30: =VLOOKUP(C30,'Crono Furui'!$C:$G,5,FALSE) -> 46269.625 | N30: =IF(M30>H30=FALSE,"ATENDE",ROUNDUP(M30-H30,0)) -> ATENDE | O30: =L30*F30 -> 0
A31: 23 | B31: 10"-B3B-MR-5203A | C31: 10"-B3B-MR-5203A-PP-2" | D31: PIPE RACK / MR LP COMPRESSOR SKID B | E31: CWP 3.1 - LIQUEFACTION | F31: 1104.1905 | G31: 9 | H31: =VLOOKUP(D31,$D$195:$F$231,3,FALSE) -> 46265.75 | I31: =VLOOKUP(H31,$H$197:$I$200,2,FALSE) -> 2º | J31: 46267 | K31: =IF(VLOOKUP(C31,'Crono Furui'!$C$2:$C$189,1,FALSE)="","VERIFICAR","OK") -> OK | L31: =VLOOKUP(C31,'Crono Furui'!$C:$G,2,FALSE) -> 0 | M31: =VLOOKUP(C31,'Crono Furui'!$C:$G,5,FALSE) -> 46260.625 | N31: =IF(M31>H31=FALSE,"ATENDE",ROUNDUP(M31-H31,0)) -> ATENDE | O31: =L31*F31 -> 0
A32: 24 | B32: 10"-B3B-MR-5203B | C32: 10"-B3B-MR-5203B-PP-2" | D32: PIPE RACK / MR HP COMPRESSOR SKID A | E32: CWP 3.1 - LIQUEFACTION | F32: 1161.466 | G32: 9 | H32: =VLOOKUP(D32,$D$195:$F$231,3,FALSE) -> 46265.75 | I32: =VLOOKUP(H32,$H$197:$I$200,2,FALSE) -> 2º | J32: 46267 | K32: =IF(VLOOKUP(C32,'Crono Furui'!$C$2:$C$189,1,FALSE)="","VERIFICAR","OK") -> OK | L32: =VLOOKUP(C32,'Crono Furui'!$C:$G,2,FALSE) -> 0 | M32: =VLOOKUP(C32,'Crono Furui'!$C:$G,5,FALSE) -> 46260.625 | N32: =IF(M32>H32=FALSE,"ATENDE",ROUNDUP(M32-H32,0)) -> ATENDE | O32: =L32*F32 -> 0
A33: 25 | B33: 16"-B3B-MR-5001A | C33: 16"-B3B-MR-5001A | D33: PIPERACK / MR LP COMPRESSOR SKID A | E33: CWP 3.1 - LIQUEFACTION | F33: 332.9846 | G33: 4 | H33: =VLOOKUP(D33,$D$195:$F$231,3,FALSE) -> 46265.75 | I33: =VLOOKUP(H33,$H$197:$I$200,2,FALSE) -> 2º | J33: 46267 | K33: =IF(VLOOKUP(C33,'Crono Furui'!$C$2:$C$189,1,FALSE)="","VERIFICAR","OK") -> OK | L33: =VLOOKUP(C33,'Crono Furui'!$C:$G,2,FALSE) -> 0 | M33: =VLOOKUP(C33,'Crono Furui'!$C:$G,5,FALSE) -> 46260.625 | N33: =IF(M33>H33=FALSE,"ATENDE",ROUNDUP(M33-H33,0)) -> ATENDE | O33: =L33*F33 -> 0
A34: 26 | B34: 16"-B3B-MR-5002A | C34: 16"-B3B-MR-5002A | D34: PIPE RACK / MR LP COMPRESSOR SKID B | E34: CWP 3.1 - LIQUEFACTION | F34: 332.9846 | G34: 4 | H34: =VLOOKUP(D34,$D$195:$F$231,3,FALSE) -> 46265.75 | I34: =VLOOKUP(H34,$H$197:$I$200,2,FALSE) -> 2º | J34: 46267 | K34: =IF(VLOOKUP(C34,'Crono Furui'!$C$2:$C$189,1,FALSE)="","VERIFICAR","OK") -> OK | L34: =VLOOKUP(C34,'Crono Furui'!$C:$G,2,FALSE) -> 0 | M34: =VLOOKUP(C34,'Crono Furui'!$C:$G,5,FALSE) -> 46260.625 | N34: =IF(M34>H34=FALSE,"ATENDE",ROUNDUP(M34-H34,0)) -> ATENDE | O34: =L34*F34 -> 0
A35: 27 | B35: 2"-A1E-BOG-7001A | C35: 2"-A1E-BOG-7001A-C-2" | D35: LNG TANK A | E35: CWP 4.1 - STORAGE TANKS | F35: 16.6122 | G35: 11 | H35: =VLOOKUP(D35,$D$195:$F$231,3,FALSE) -> 46287.75 | I35: =VLOOKUP(H35,$H$197:$I$200,2,FALSE) -> 4º | K35: =IF(VLOOKUP(C35,'Crono Furui'!$C$2:$C$189,1,FALSE)="","VERIFICAR","OK") -> OK | L35: =VLOOKUP(C35,'Crono Furui'!$C:$G,2,FALSE) -> 0 | M35: =VLOOKUP(C35,'Crono Furui'!$C:$G,5,FALSE) -> 46281.625 | N35: =IF(M35>H35=FALSE,"ATENDE",ROUNDUP(M35-H35,0)) -> ATENDE | O35: =L35*F35 -> 0
A36: 28 | B36: 2"-A1E-BOG-7002A | C36: 2"-A1E-BOG-7002A-C-2" | D36: LNG TANK B | E36: CWP 4.1 - STORAGE TANKS | F36: 16.5725 | G36: 11 | H36: =VLOOKUP(D36,$D$195:$F$231,3,FALSE) -> 46287.75 | I36: =VLOOKUP(H36,$H$197:$I$200,2,FALSE) -> 4º | K36: =IF(VLOOKUP(C36,'Crono Furui'!$C$2:$C$189,1,FALSE)="","VERIFICAR","OK") -> OK | L36: =VLOOKUP(C36,'Crono Furui'!$C:$G,2,FALSE) -> 0 | M36: =VLOOKUP(C36,'Crono Furui'!$C:$G,5,FALSE) -> 46281.625 | N36: =IF(M36>H36=FALSE,"ATENDE",ROUNDUP(M36-H36,0)) -> ATENDE | O36: =L36*F36 -> 0
A37: 29 | B37: 2"-A1E-BOG-7003B | C37: 2"-A1E-BOG-7003B-C-2" | D37: LNG TANK C | E37: CWP 4.1 - STORAGE TANKS | F37: 16.7313 | G37: 11 | H37: =VLOOKUP(D37,$D$195:$F$231,3,FALSE) -> 46287.75 | I37: =VLOOKUP(H37,$H$197:$I$200,2,FALSE) -> 4º | K37: =IF(VLOOKUP(C37,'Crono Furui'!$C$2:$C$189,1,FALSE)="","VERIFICAR","OK") -> OK | L37: =VLOOKUP(C37,'Crono Furui'!$C:$G,2,FALSE) -> 0 | M37: =VLOOKUP(C37,'Crono Furui'!$C:$G,5,FALSE) -> 46281.625 | N37: =IF(M37>H37=FALSE,"ATENDE",ROUNDUP(M37-H37,0)) -> ATENDE | O37: =L37*F37 -> 0
A38: 30 | B38: 2"-A1E-BOG-7004B | C38: 2"-A1E-BOG-7004B-C-2" | D38: LNG TANK D | E38: CWP 4.1 - STORAGE TANKS | F38: 16.6122 | G38: 11 | H38: =VLOOKUP(D38,$D$195:$F$231,3,FALSE) -> 46287.75 | I38: =VLOOKUP(H38,$H$197:$I$200,2,FALSE) -> 4º | K38: =IF(VLOOKUP(C38,'Crono Furui'!$C$2:$C$189,1,FALSE)="","VERIFICAR","OK") -> OK | L38: =VLOOKUP(C38,'Crono Furui'!$C:$G,2,FALSE) -> 0 | M38: =VLOOKUP(C38,'Crono Furui'!$C:$G,5,FALSE) -> 46281.625 | N38: =IF(M38>H38=FALSE,"ATENDE",ROUNDUP(M38-H38,0)) -> ATENDE | O38: =L38*F38 -> 0
A39: 31 | B39: 2"-A1E-BOG-7005C | C39: 2"-A1E-BOG-7005C-C-2" | D39: LNG TANK E | E39: CWP 4.1 - STORAGE TANKS | F39: 16.6519 | G39: 11 | H39: =VLOOKUP(D39,$D$195:$F$231,3,FALSE) -> 46287.75 | I39: =VLOOKUP(H39,$H$197:$I$200,2,FALSE) -> 4º | K39: =IF(VLOOKUP(C39,'Crono Furui'!$C$2:$C$189,1,FALSE)="","VERIFICAR","OK") -> OK | L39: =VLOOKUP(C39,'Crono Furui'!$C:$G,2,FALSE) -> 0 | M39: =VLOOKUP(C39,'Crono Furui'!$C:$G,5,FALSE) -> 46282.583 | N39: =IF(M39>H39=FALSE,"ATENDE",ROUNDUP(M39-H39,0)) -> ATENDE | O39: =L39*F39 -> 0
A40: 32 | B40: 2"-A1E-BOG-7006A | C40: 2"-A1E-BOG-7006A-C-3" | D40: LNG TANK A | E40: CWP 4.1 - STORAGE TANKS | F40: 20.6775 | G40: 9 | H40: =VLOOKUP(D40,$D$195:$F$231,3,FALSE) -> 46287.75 | I40: =VLOOKUP(H40,$H$197:$I$200,2,FALSE) -> 4º | K40: =IF(VLOOKUP(C40,'Crono Furui'!$C$2:$C$189,1,FALSE)="","VERIFICAR","OK") -> OK | L40: =VLOOKUP(C40,'Crono Furui'!$C:$G,2,FALSE) -> 0 | M40: =VLOOKUP(C40,'Crono Furui'!$C:$G,5,FALSE) -> 46282.583 | N40: =IF(M40>H40=FALSE,"ATENDE",ROUNDUP(M40-H40,0)) -> ATENDE | O40: =L40*F40 -> 0
...

Sheet Planilha1
L5: 1º Lote (1A) – Entrega dia 20/08 no site
L7: 1""-A1E-CF-4310A" – Fornecido 22/08
L8: 1""-B1E-MR-4005A"– Fornecido 22/08
L9: 1""-B1E-MR-4006A"– Fornecido 22/08
L10: 1""-B1E-MR-4007A"– Fornecido 22/08
L11: "1""-B1E-MR-4008A"– Fornecido 22/08
L12: "1""-B1E-MR-4009A"– Fornecido 22/08
L13: "1""-B3B-LO-5003A"– Fornecido 22/08
L14: "1""-D1E-LPG-4305A-C-3"""– Fornecido 22/08
L15: "1""-D1E-LPG-4308A-C-3"""– Fornecido 22/08
L16: "1""-D1E-NG-4001A"– Fornecido 22/08
L17: "1""-D3B-NG-3105A"– Não fornecido
... L40: "2""-A1E-IA-9011"– Não fornecido
